<?xml version="1.0" ?>
<!-- =================================================================================== -->
<!-- |    This document was autogenerated by xacro from arm.urdf.xacro                 | -->
<!-- |    EDITING THIS FILE BY HAND IS NOT RECOMMENDED                                 | -->
<!-- =================================================================================== -->
<robot name="turtlebot_arm" xmlns:controller="http://playerstage.sourceforge.net/gazebo/xmlschema/#controller" xmlns:interface="http://playerstage.sourceforge.net/gazebo/xmlschema/#interface" xmlns:sensor="http://playerstage.sourceforge.net/gazebo/xmlschema/#sensor">
  <!-- Included URDF Files -->
  <!--<include filename="$(find turtlebot_description)/urdf/turtlebot.urdf.xacro" />-->
  <material name="white">
    <color rgba="0.87 0.90 0.87 1.0"/>
  </material>
  <material name="black">
    <color rgba="0.0 0.0 0.0 1.0"/>
  </material>
  <material name="green">
    <color rgba="0.22 0.32 0.14 1.0"/>
  </material>
  <!-- For now I have removed the turtlebot since this all moved around..
    <turtlebot />-->
  <!-- Instead, there is a base_link -->
  <link name="base_link"/>
  <link name="arm_base_link"/>
  <joint name="arm_base_joint" type="fixed">
    <origin xyz="0 0 0"/>
    <parent link="base_link"/>
    <child link="arm_base_link"/>
  </joint>
  <link name="gripper_link"/>
  <joint name="gripper_link_joint" type="revolute">
    <origin rpy="0 -1.57 0" xyz="0 0 .112"/>
    <parent link="arm_wrist_flex_link"/>
    <child link="gripper_link"/>
    <limit effort="30" lower="-3.14" upper="3.14" velocity="1"/>
    <axis xyz="1 0 0"/>
  </joint>
  <joint name="arm_shoulder_pan_servo_joint" type="fixed">
    <origin rpy="1.570795 0 1.570795" xyz="0 0 0"/>
    <parent link="arm_base_link"/>
    <child link="arm_shoulder_pan_servo_link"/>
  </joint>
  <link name="arm_shoulder_pan_servo_link">
    <inertial>
      <mass value="0.00001"/>
      <origin xyz="0 0 0"/>
      <inertia ixx="1.0" ixy="0.0" ixz="0.0" iyy="1.0" iyz="0.0" izz="1.0"/>
    </inertial>
    <visual>
      <origin rpy="0 0 0" xyz=" 0 0 0 "/>
      <geometry>
        <mesh filename="package://turtlebot_arm_description/meshes/ax12_box.stl" scale="0.001 0.001 0.001"/>
      </geometry>
      <material name="black"/>
    </visual>
    <collision>
      <origin rpy="0 0 0" xyz="0.0 0.0 -0.01241"/>
      <geometry>
        <box size="0.025 0.038 0.04762"/>
      </geometry>
    </collision>
  </link>
  <joint name="arm_shoulder_pan_joint" type="revolute">
    <origin rpy="-1.570795 1.570795 3.14159" xyz="0 0.019 0"/>
    <axis xyz="0 0 -1"/>
    <limit effort="30" lower="-2.617" upper="2.617" velocity="0.785"/>
    <parent link="arm_shoulder_pan_servo_link"/>
    <child link="arm_shoulder_pan_link"/>
  </joint>
  <link name="arm_shoulder_pan_link">
    <inertial>
      <mass value="0.00001"/>
      <origin xyz="0 0 0"/>
      <inertia ixx="1.0" ixy="0.0" ixz="0.0" iyy="1.0" iyz="0.0" izz="1.0"/>
    </inertial>
    <visual>
      <origin rpy="0 0 0" xyz=" 0 0 0 "/>
      <geometry>
        <mesh filename="package://turtlebot_arm_description/meshes/F3.stl" scale="0.001 0.001 0.001"/>
      </geometry>
      <material name="white"/>
    </visual>
    <collision>
      <origin rpy="0 0 0" xyz="0.0 0.0 -0.0045"/>
      <geometry>
        <box size="0.025 0.038 0.009"/>
      </geometry>
    </collision>
  </link>
  <joint name="arm_shoulder_lift_servo_joint" type="fixed">
    <origin rpy="0 3.14159 0" xyz="0 0 -0.0415"/>
    <parent link="arm_shoulder_pan_link"/>
    <child link="arm_shoulder_lift_servo_link"/>
  </joint>
  <link name="arm_shoulder_lift_servo_link">
    <inertial>
      <mass value="0.00001"/>
      <origin xyz="0 0 0"/>
      <inertia ixx="1.0" ixy="0.0" ixz="0.0" iyy="1.0" iyz="0.0" izz="1.0"/>
    </inertial>
    <visual>
      <origin rpy="0 0 0" xyz=" 0 0 0 "/>
      <geometry>
        <mesh filename="package://turtlebot_arm_description/meshes/ax12_box.stl" scale="0.001 0.001 0.001"/>
      </geometry>
      <material name="black"/>
    </visual>
    <collision>
      <origin rpy="0 0 0" xyz="0.0 0.0 -0.01241"/>
      <geometry>
        <box size="0.025 0.038 0.04762"/>
      </geometry>
    </collision>
  </link>
  <joint name="arm_shoulder_lift_joint" type="revolute">
    <origin rpy="0 0 0" xyz="0 0 0"/>
    <axis xyz="0 1 0"/>
    <limit effort="30" lower="-2.617" upper="2.617" velocity="1.571"/>
    <parent link="arm_shoulder_lift_servo_link"/>
    <child link="arm_shoulder_lift_link"/>
  </joint>
  <link name="arm_shoulder_lift_link">
    <inertial>
      <mass value="0.00001"/>
      <origin xyz="0 0 0"/>
      <inertia ixx="1.0" ixy="0.0" ixz="0.0" iyy="1.0" iyz="0.0" izz="1.0"/>
    </inertial>
    <visual>
      <origin rpy="0 0 0" xyz=" 0 0 0 "/>
      <geometry>
        <mesh filename="package://turtlebot_arm_description/meshes/F4.stl" scale="0.001 0.001 0.001"/>
      </geometry>
      <material name="white"/>
    </visual>
    <collision>
      <origin rpy="0 0 0" xyz="0.0 0.0 0.0215"/>
      <geometry>
        <box size="0.028 0.0485 0.065"/>
      </geometry>
    </collision>
  </link>
  <joint name="arm_shoulder_F10_0_joint" type="fixed">
    <origin rpy="0 0 0" xyz="0 0 0.0545"/>
    <parent link="arm_shoulder_lift_link"/>
    <child link="arm_shoulder_F10_0_link"/>
  </joint>
  <link name="arm_shoulder_F10_0_link">
    <inertial>
      <mass value="0.00001"/>
      <origin xyz="0 0 0"/>
      <inertia ixx="1.0" ixy="0.0" ixz="0.0" iyy="1.0" iyz="0.0" izz="1.0"/>
    </inertial>
    <visual>
      <origin rpy="0 0 0" xyz=" 0 0 0 "/>
      <geometry>
        <mesh filename="package://turtlebot_arm_description/meshes/F10.stl" scale="0.001 0.001 0.001"/>
      </geometry>
      <material name="white"/>
    </visual>
    <collision>
      <origin rpy="0 0 0" xyz="0.0 0.0 0.0"/>
      <geometry>
        <box size="0.025 0.038 0.004"/>
      </geometry>
    </collision>
  </link>
  <joint name="arm_shoulder_F10_1_joint" type="fixed">
    <origin rpy="0 0 0" xyz="0 0 0.004"/>
    <parent link="arm_shoulder_F10_0_link"/>
    <child link="arm_shoulder_F10_1_link"/>
  </joint>
  <link name="arm_shoulder_F10_1_link">
    <inertial>
      <mass value="0.00001"/>
      <origin xyz="0 0 0"/>
      <inertia ixx="1.0" ixy="0.0" ixz="0.0" iyy="1.0" iyz="0.0" izz="1.0"/>
    </inertial>
    <visual>
      <origin rpy="0 0 0" xyz=" 0 0 0 "/>
      <geometry>
        <mesh filename="package://turtlebot_arm_description/meshes/F10.stl" scale="0.001 0.001 0.001"/>
      </geometry>
      <material name="white"/>
    </visual>
    <collision>
      <origin rpy="0 0 0" xyz="0.0 0.0 0.0"/>
      <geometry>
        <box size="0.025 0.038 0.004"/>
      </geometry>
    </collision>
  </link>
  <joint name="arm_shoulder_F10_2_joint" type="fixed">
    <origin rpy="0 0 0" xyz="0 0 0.004"/>
    <parent link="arm_shoulder_F10_1_link"/>
    <child link="arm_shoulder_F10_2_link"/>
  </joint>
  <link name="arm_shoulder_F10_2_link">
    <inertial>
      <mass value="0.00001"/>
      <origin xyz="0 0 0"/>
      <inertia ixx="1.0" ixy="0.0" ixz="0.0" iyy="1.0" iyz="0.0" izz="1.0"/>
    </inertial>
    <visual>
      <origin rpy="0 0 0" xyz=" 0 0 0 "/>
      <geometry>
        <mesh filename="package://turtlebot_arm_description/meshes/F10.stl" scale="0.001 0.001 0.001"/>
      </geometry>
      <material name="white"/>
    </visual>
    <collision>
      <origin rpy="0 0 0" xyz="0.0 0.0 0.0"/>
      <geometry>
        <box size="0.025 0.038 0.004"/>
      </geometry>
    </collision>
  </link>
  <joint name="arm_shoulder_F3_0_joint" type="fixed">
    <origin rpy="0 3.14159 0" xyz="0 0 0.002"/>
    <parent link="arm_shoulder_F10_2_link"/>
    <child link="arm_shoulder_F3_0_link"/>
  </joint>
  <link name="arm_shoulder_F3_0_link">
    <inertial>
      <mass value="0.00001"/>
      <origin xyz="0 0 0"/>
      <inertia ixx="1.0" ixy="0.0" ixz="0.0" iyy="1.0" iyz="0.0" izz="1.0"/>
    </inertial>
    <visual>
      <origin rpy="0 0 0" xyz=" 0 0 0 "/>
      <geometry>
        <mesh filename="package://turtlebot_arm_description/meshes/F3.stl" scale="0.001 0.001 0.001"/>
      </geometry>
      <material name="white"/>
    </visual>
    <collision>
      <origin rpy="0 0 0" xyz="0.0 0.0 -0.0045"/>
      <geometry>
        <box size="0.025 0.038 0.009"/>
      </geometry>
    </collision>
  </link>
  <joint name="arm_elbow_flex_servo_joint" type="fixed">
    <origin rpy="0 3.14159 0" xyz="0 0 -0.0415"/>
    <parent link="arm_shoulder_F3_0_link"/>
    <child link="arm_elbow_flex_servo_link"/>
  </joint>
  <link name="arm_elbow_flex_servo_link">
    <inertial>
      <mass value="0.00001"/>
      <origin xyz="0 0 0"/>
      <inertia ixx="1.0" ixy="0.0" ixz="0.0" iyy="1.0" iyz="0.0" izz="1.0"/>
    </inertial>
    <visual>
      <origin rpy="0 0 0" xyz=" 0 0 0 "/>
      <geometry>
        <mesh filename="package://turtlebot_arm_description/meshes/ax12_box.stl" scale="0.001 0.001 0.001"/>
      </geometry>
      <material name="black"/>
    </visual>
    <collision>
      <origin rpy="0 0 0" xyz="0.0 0.0 -0.01241"/>
      <geometry>
        <box size="0.025 0.038 0.04762"/>
      </geometry>
    </collision>
  </link>
  <joint name="arm_elbow_flex_joint" type="revolute">
    <origin rpy="0 0 0" xyz="0 0 0"/>
    <axis xyz="0 1 0"/>
    <limit effort="30" lower="-2.617" upper="2.617" velocity="1.571"/>
    <parent link="arm_elbow_flex_servo_link"/>
    <child link="arm_elbow_flex_link"/>
  </joint>
  <link name="arm_elbow_flex_link">
    <inertial>
      <mass value="0.00001"/>
      <origin xyz="0 0 0"/>
      <inertia ixx="1.0" ixy="0.0" ixz="0.0" iyy="1.0" iyz="0.0" izz="1.0"/>
    </inertial>
    <visual>
      <origin rpy="0 0 0" xyz=" 0 0 0 "/>
      <geometry>
        <mesh filename="package://turtlebot_arm_description/meshes/F4.stl" scale="0.001 0.001 0.001"/>
      </geometry>
      <material name="white"/>
    </visual>
    <collision>
      <origin rpy="0 0 0" xyz="0.0 0.0 0.0215"/>
      <geometry>
        <box size="0.028 0.0485 0.065"/>
      </geometry>
    </collision>
  </link>
  <joint name="arm_elbow_F10_0_joint" type="fixed">
    <origin rpy="0 0 0" xyz="0 0 0.0545"/>
    <parent link="arm_elbow_flex_link"/>
    <child link="arm_elbow_F10_0_link"/>
  </joint>
  <link name="arm_elbow_F10_0_link">
    <inertial>
      <mass value="0.00001"/>
      <origin xyz="0 0 0"/>
      <inertia ixx="1.0" ixy="0.0" ixz="0.0" iyy="1.0" iyz="0.0" izz="1.0"/>
    </inertial>
    <visual>
      <origin rpy="0 0 0" xyz=" 0 0 0 "/>
      <geometry>
        <mesh filename="package://turtlebot_arm_description/meshes/F10.stl" scale="0.001 0.001 0.001"/>
      </geometry>
      <material name="white"/>
    </visual>
    <collision>
      <origin rpy="0 0 0" xyz="0.0 0.0 0.0"/>
      <geometry>
        <box size="0.025 0.038 0.004"/>
      </geometry>
    </collision>
  </link>
  <joint name="arm_elbow_F10_1_joint" type="fixed">
    <origin rpy="0 0 0" xyz="0 0 0.004"/>
    <parent link="arm_elbow_F10_0_link"/>
    <child link="arm_elbow_F10_1_link"/>
  </joint>
  <link name="arm_elbow_F10_1_link">
    <inertial>
      <mass value="0.00001"/>
      <origin xyz="0 0 0"/>
      <inertia ixx="1.0" ixy="0.0" ixz="0.0" iyy="1.0" iyz="0.0" izz="1.0"/>
    </inertial>
    <visual>
      <origin rpy="0 0 0" xyz=" 0 0 0 "/>
      <geometry>
        <mesh filename="package://turtlebot_arm_description/meshes/F10.stl" scale="0.001 0.001 0.001"/>
      </geometry>
      <material name="white"/>
    </visual>
    <collision>
      <origin rpy="0 0 0" xyz="0.0 0.0 0.0"/>
      <geometry>
        <box size="0.025 0.038 0.004"/>
      </geometry>
    </collision>
  </link>
  <joint name="arm_elbow_F10_2_joint" type="fixed">
    <origin rpy="0 0 0" xyz="0 0 0.004"/>
    <parent link="arm_elbow_F10_1_link"/>
    <child link="arm_elbow_F10_2_link"/>
  </joint>
  <link name="arm_elbow_F10_2_link">
    <inertial>
      <mass value="0.00001"/>
      <origin xyz="0 0 0"/>
      <inertia ixx="1.0" ixy="0.0" ixz="0.0" iyy="1.0" iyz="0.0" izz="1.0"/>
    </inertial>
    <visual>
      <origin rpy="0 0 0" xyz=" 0 0 0 "/>
      <geometry>
        <mesh filename="package://turtlebot_arm_description/meshes/F10.stl" scale="0.001 0.001 0.001"/>
      </geometry>
      <material name="white"/>
    </visual>
    <collision>
      <origin rpy="0 0 0" xyz="0.0 0.0 0.0"/>
      <geometry>
        <box size="0.025 0.038 0.004"/>
      </geometry>
    </collision>
  </link>
  <joint name="arm_elbow_F3_0_joint" type="fixed">
    <origin rpy="0 3.14159 0" xyz="0 0 0.002"/>
    <parent link="arm_elbow_F10_2_link"/>
    <child link="arm_elbow_F3_0_link"/>
  </joint>
  <link name="arm_elbow_F3_0_link">
    <inertial>
      <mass value="0.00001"/>
      <origin xyz="0 0 0"/>
      <inertia ixx="1.0" ixy="0.0" ixz="0.0" iyy="1.0" iyz="0.0" izz="1.0"/>
    </inertial>
    <visual>
      <origin rpy="0 0 0" xyz=" 0 0 0 "/>
      <geometry>
        <mesh filename="package://turtlebot_arm_description/meshes/F3.stl" scale="0.001 0.001 0.001"/>
      </geometry>
      <material name="white"/>
    </visual>
    <collision>
      <origin rpy="0 0 0" xyz="0.0 0.0 -0.0045"/>
      <geometry>
        <box size="0.025 0.038 0.009"/>
      </geometry>
    </collision>
  </link>
  <joint name="arm_wrist_flex_servo_joint" type="fixed">
    <origin rpy="0 3.14159 0" xyz="0 0 -0.0415"/>
    <parent link="arm_elbow_F3_0_link"/>
    <child link="arm_wrist_flex_servo_link"/>
  </joint>
  <link name="arm_wrist_flex_servo_link">
    <inertial>
      <mass value="0.00001"/>
      <origin xyz="0 0 0"/>
      <inertia ixx="1.0" ixy="0.0" ixz="0.0" iyy="1.0" iyz="0.0" izz="1.0"/>
    </inertial>
    <visual>
      <origin rpy="0 0 0" xyz=" 0 0 0 "/>
      <geometry>
        <mesh filename="package://turtlebot_arm_description/meshes/ax12_box.stl" scale="0.001 0.001 0.001"/>
      </geometry>
      <material name="black"/>
    </visual>
    <collision>
      <origin rpy="0 0 0" xyz="0.0 0.0 -0.01241"/>
      <geometry>
        <box size="0.025 0.038 0.04762"/>
      </geometry>
    </collision>
  </link>
  <joint name="arm_wrist_flex_joint" type="revolute">
    <origin rpy="0 0 0" xyz="0 0 0"/>
    <axis xyz="0 1 0"/>
    <limit effort="30" lower="-1.745" upper="1.745" velocity="1.571"/>
    <parent link="arm_wrist_flex_servo_link"/>
    <child link="arm_wrist_flex_link"/>
  </joint>
  <link name="arm_wrist_flex_link">
    <inertial>
      <mass value="0.00001"/>
      <origin xyz="0 0 0"/>
      <inertia ixx="1.0" ixy="0.0" ixz="0.0" iyy="1.0" iyz="0.0" izz="1.0"/>
    </inertial>
    <visual>
      <origin rpy="0 0 0" xyz=" 0 0 0 "/>
      <geometry>
        <mesh filename="package://turtlebot_arm_description/meshes/F2.stl" scale="0.001 0.001 0.001"/>
      </geometry>
      <material name="white"/>
    </visual>
    <collision>
      <origin rpy="0 0 0" xyz="0.0 0.0 0.00775"/>
      <geometry>
        <box size="0.025 0.0485 0.0375"/>
      </geometry>
    </collision>
  </link>
  <joint name="arm_wrist_F3_0_joint" type="fixed">
    <origin rpy="0 3.14159 -1.570795" xyz="0 0.016 0.0265"/>
    <parent link="arm_wrist_flex_link"/>
    <child link="arm_wrist_F3_0_link"/>
  </joint>
  <link name="arm_wrist_F3_0_link">
    <inertial>
      <mass value="0.00001"/>
      <origin xyz="0 0 0"/>
      <inertia ixx="1.0" ixy="0.0" ixz="0.0" iyy="1.0" iyz="0.0" izz="1.0"/>
    </inertial>
    <visual>
      <origin rpy="0 0 0" xyz=" 0 0 0 "/>
      <geometry>
        <mesh filename="package://turtlebot_arm_description/meshes/F3.stl" scale="0.001 0.001 0.001"/>
      </geometry>
      <material name="white"/>
    </visual>
    <collision>
      <origin rpy="0 0 0" xyz="0.0 0.0 -0.0045"/>
      <geometry>
        <box size="0.025 0.038 0.009"/>
      </geometry>
    </collision>
  </link>
  <joint name="gripper_servo_joint" type="fixed">
    <origin rpy="3.14159 1.570795 0" xyz="-0.02275 0 -0.019"/>
    <parent link="arm_wrist_F3_0_link"/>
    <child link="gripper_servo_link"/>
  </joint>
  <link name="gripper_servo_link">
    <inertial>
      <mass value="0.00001"/>
      <origin xyz="0 0 0"/>
      <inertia ixx="1.0" ixy="0.0" ixz="0.0" iyy="1.0" iyz="0.0" izz="1.0"/>
    </inertial>
    <visual>
      <origin rpy="0 0 0" xyz=" 0 0 0 "/>
      <geometry>
        <mesh filename="package://turtlebot_arm_description/meshes/ax12_box.stl" scale="0.001 0.001 0.001"/>
      </geometry>
      <material name="black"/>
    </visual>
    <collision>
      <origin rpy="0 0 0" xyz="0.0 0.0 -0.01241"/>
      <geometry>
        <box size="0.025 0.038 0.04762"/>
      </geometry>
    </collision>
  </link>
  <joint name="gripper_joint" type="revolute">
    <origin rpy="0 0 0" xyz="0 0 0"/>
    <axis xyz="0 1 0"/>
    <limit effort="30" lower="-0.060" upper="0.50" velocity="0.785"/>
    <parent link="gripper_servo_link"/>
    <child link="gripper_active_link"/>
  </joint>
  <link name="gripper_active_link">
    <inertial>
      <mass value="0.00001"/>
      <origin xyz="0 0 0"/>
      <inertia ixx="1.0" ixy="0.0" ixz="0.0" iyy="1.0" iyz="0.0" izz="1.0"/>
    </inertial>
    <visual>
      <origin rpy="0 0 0" xyz=" 0 0 0 "/>
      <geometry>
        <mesh filename="package://turtlebot_arm_description/meshes/F2.stl" scale="0.001 0.001 0.001"/>
      </geometry>
      <material name="white"/>
    </visual>
    <collision>
      <origin rpy="0 0 0" xyz="0.0 0.0 0.00775"/>
      <geometry>
        <box size="0.025 0.0485 0.0375"/>
      </geometry>
    </collision>
  </link>
  <joint name="gripper_active_finger_joint" type="fixed">
    <origin rpy="0 0 0" xyz="0 0 0.0265"/>
    <parent link="gripper_active_link"/>
    <child link="gripper_active_finger_link"/>
  </joint>
  <link name="gripper_active_finger_link">
    <inertial>
      <mass value="0.00001"/>
      <origin xyz="0 0 0"/>
      <inertia ixx="1.0" ixy="0.0" ixz="0.0" iyy="1.0" iyz="0.0" izz="1.0"/>
    </inertial>
    <visual>
      <origin rpy="0 0 0" xyz=" 0 0 0 "/>
      <geometry>
        <mesh filename="package://turtlebot_arm_description/meshes/finger.stl" scale="0.001 0.001 0.001"/>
      </geometry>
      <material name="green"/>
    </visual>
    <collision>
      <origin rpy="0 0 0" xyz="0.02645 0.0 -0.00655"/>
      <geometry>
        <box size="0.0783 0.03801 0.0193"/>
      </geometry>
    </collision>
  </link>
  <joint name="gripper_static_joint" type="fixed">
    <origin rpy="0 3.14159 0" xyz="0 0 -0.0415"/>
    <parent link="gripper_servo_link"/>
    <child link="gripper_static_link"/>
  </joint>
  <link name="gripper_static_link">
    <inertial>
      <mass value="0.00001"/>
      <origin xyz="0 0 0"/>
      <inertia ixx="1.0" ixy="0.0" ixz="0.0" iyy="1.0" iyz="0.0" izz="1.0"/>
    </inertial>
    <visual>
      <origin rpy="0 0 0" xyz=" 0 0 0 "/>
      <geometry>
        <mesh filename="package://turtlebot_arm_description/meshes/F3.stl" scale="0.001 0.001 0.001"/>
      </geometry>
      <material name="white"/>
    </visual>
    <collision>
      <origin rpy="0 0 0" xyz="0.0 0.0 -0.0045"/>
      <geometry>
        <box size="0.025 0.038 0.009"/>
      </geometry>
    </collision>
  </link>
  <joint name="gripper_static_finger_joint" type="fixed">
    <origin rpy="0 0 3.14159" xyz="0 0 0"/>
    <parent link="gripper_static_link"/>
    <child link="gripper_static_finger_link"/>
  </joint>
  <link name="gripper_static_finger_link">
    <inertial>
      <mass value="0.00001"/>
      <origin xyz="0 0 0"/>
      <inertia ixx="1.0" ixy="0.0" ixz="0.0" iyy="1.0" iyz="0.0" izz="1.0"/>
    </inertial>
    <visual>
      <origin rpy="0 0 0" xyz=" 0 0 0 "/>
      <geometry>
        <mesh filename="package://turtlebot_arm_description/meshes/finger.stl" scale="0.001 0.001 0.001"/>
      </geometry>
      <material name="green"/>
    </visual>
    <collision>
      <origin rpy="0 0 0" xyz="0.02645 0.0 -0.00655"/>
      <geometry>
        <box size="0.0783 0.03801 0.0193"/>
      </geometry>
    </collision>
  </link>
</robot>

