<?xml version="1.0"?>
<!-- Basic URDF components for Turtlebot Arm and PhantomX Pincher Arm-->
<robot xmlns:xacro="http://ros.org/wiki/xacro">
  <xacro:property name="M_PI" value="3.14159"/>
  <xacro:property name="M_SCALE" value="0.001"/>
  <xacro:property name="F10_HEIGHT" value="0.004"/>
  <xacro:property name="F4_HEIGHT" value="0.0525"/>
  <xacro:property name="F3_HEIGHT" value="0.009"/>
  <xacro:property name="AX12_HEIGHT" value="0.0385"/>
  <xacro:property name="AX12_WIDTH" value="0.038"/>
  <xacro:property name="AX12_LENGTH" value="0.050"/>
  <xacro:property name="F2_HEIGHT" value="0.0265"/>

  <!-- Calculates the inertial properties of a bounding box. From
       https://en.wikipedia.org/wiki/List_of_moments_of_inertia#List_of_3D_inertia_tensors-->
  <xacro:macro name="box_inertia" params="length width height mass">
    <inertial>
      <mass value="${mass}"/>
      <origin xyz="0 0 0"/>
      <inertia ixx="${mass/12*(height**2+length**2)}" ixy="0" ixz = "0"
               iyy="${mass/12*(width**2+length**2)}" iyz="0"
               izz="${mass/12*(width**2+height**2)}"/>
    </inertial>
  </xacro:macro>

  <xacro:macro name="arm_mount" params="parent name color *origin">
    <joint name="${name}_joint" type="fixed">
      <xacro:insert_block name="origin"/>
      <parent link="${parent}"/>
      <child link="${name}_link"/>
    </joint>

    <link name="${name}_link">
      <xacro:box_inertia length="0.074" width="0.074" height="0.004" mass="0.018"/>

      <visual>
        <origin xyz="-0.028 -0.0493 0.014" rpy="0.0 0.0 -${M_PI/2}"/>
        <geometry>
          <mesh filename="package://turtlebot_arm_description/meshes/mount.stl" scale="${M_SCALE} ${M_SCALE} ${M_SCALE}"/>
        </geometry>
        <material name="${color}"/>
      </visual>

      <collision>
        <origin xyz="-0.01 0.0 0.0165" rpy="0.0 0.0 0.0"/>
        <geometry>
          <box size="0.074 0.074 0.004"/>
        </geometry>
      </collision>
    </link>
    
    <gazebo reference="${name}_link">
      <material>Gazebo/${color}</material>
      <selfCollide>true</selfCollide>
      <gravity>true</gravity>
    </gazebo>
  </xacro:macro>

  <xacro:macro name="finger_fixed" params="parent name color *origin">
    <joint name="${name}_joint" type="fixed">
      <xacro:insert_block name="origin"/>
      <parent link="${parent}"/>
      <child link="${name}_link"/>
    </joint>

    <link name="${name}_link">
      <xacro:box_inertia length="0.0783" width="0.03801" height="0.0193" mass="0.015"/>

      <visual>
        <origin xyz=" 0 0 0 " rpy="0 0 0"/>
        <geometry>
          <mesh filename="package://turtlebot_arm_description/meshes/turtlebot_finger.stl" scale="${M_SCALE} ${M_SCALE} ${M_SCALE}"/>
        </geometry>
        <material name="${color}"/>
      </visual>

      <collision>
        <origin xyz="0.02645 0.0 -0.00655" rpy="0 0 0"/>
        <geometry>
          <box size="0.0783 0.03801 0.0193"/>
        </geometry>
      </collision>
    </link>
    
    <gazebo reference="${name}_link">
      <material>Gazebo/${color}</material>
      <selfCollide>true</selfCollide>
      <gravity>true</gravity>
    </gazebo>
  </xacro:macro>

  <xacro:macro name="dynamixel_AX12_fixed" params="parent name *origin">
    <joint name="${name}_joint" type="fixed">
      <xacro:insert_block name="origin"/>
      <parent link="${parent}"/>
      <child link="${name}_link"/>
    </joint>

    <link name="${name}_link">
      <inertial>
        <mass value="0.055"/>
        <origin xyz="0 0 0"/>
        <inertia ixx="0.000017012" ixy="0.0" ixz="0.0"
                 iyy="0.000013258" iyz="0.0"
                 izz="0.000009483"/>
      </inertial>

      <visual>
        <origin xyz=" 0 0 0 " rpy="0 0 0"/>
        <geometry>
          <mesh filename="package://turtlebot_arm_description/meshes/ax12_box.stl" scale="${M_SCALE} ${M_SCALE} ${M_SCALE}"/>
        </geometry>
        <material name="Black"/>
      </visual>

      <collision>
        <origin xyz="0.0 0.0 -0.01241" rpy="0 0 0"/>
        <geometry>
          <box size="0.025 0.038 0.04762"/>
        </geometry>
      </collision>
    </link>
    
    <gazebo reference="${name}_link">
      <material>Gazebo/Black</material>
      <selfCollide>true</selfCollide>
      <gravity>true</gravity>
    </gazebo>
  </xacro:macro>

  <xacro:macro name="bioloid_F10_fixed" params="parent name color *origin">
    <joint name="${name}_joint" type="fixed">
      <xacro:insert_block name="origin"/>
      <parent link="${parent}"/>
      <child link="${name}_link"/>
    </joint>

    <link name="${name}_link">
      <xacro:box_inertia length="0.025" width="0.038" height="0.004" mass="0.004"/>

      <visual>
        <origin xyz=" 0 0 0 " rpy="0 0 0"/>
        <geometry>
          <mesh filename="package://turtlebot_arm_description/meshes/F10.stl" scale="${M_SCALE} ${M_SCALE} ${M_SCALE}"/>
        </geometry>
        <material name="${color}"/>
      </visual>

      <collision>
        <origin xyz="0.0 0.0 0.0" rpy="0 0 0"/>
        <geometry>
          <box size="0.025 0.038 0.004"/>
        </geometry>
      </collision>
    </link>
    
    <gazebo reference="${name}_link">
      <material>Gazebo/${color}</material>
      <selfCollide>true</selfCollide>
      <gravity>true</gravity>
    </gazebo>
  </xacro:macro>

  <xacro:macro name="bioloid_F3_fixed" params="parent name color *origin">
    <joint name="${name}_joint" type="fixed">
      <xacro:insert_block name="origin"/>
      <parent link="${parent}"/>
      <child link="${name}_link"/>
    </joint>

    <link name="${name}_link">
      <xacro:box_inertia length="0.025" width="0.038" height="0.009" mass="0.005"/>

      <visual>
        <origin xyz=" 0 0 0 " rpy="0 0 0"/>
        <geometry>
          <mesh filename="package://turtlebot_arm_description/meshes/F3.stl" scale="${M_SCALE} ${M_SCALE} ${M_SCALE}"/>
        </geometry>
        <material name="${color}"/>
      </visual>

      <collision>
        <origin xyz="0.0 0.0 -0.0045" rpy="0 0 0"/>
        <geometry>
          <box size="0.025 0.038 0.009"/>
        </geometry>
      </collision>
    </link>
    
    <gazebo reference="${name}_link">
      <material>Gazebo/${color}</material>
      <selfCollide>true</selfCollide>
      <gravity>true</gravity>
    </gazebo>
  </xacro:macro>

  <xacro:macro name="bioloid_F3_revolute" params="parent name color llimit ulimit vlimit *origin">
    <joint name="${name}_joint" type="revolute">
      <xacro:insert_block name="origin"/>
      <axis xyz="0 0 -1"/>
      <limit effort="30" velocity="${vlimit}" lower="${llimit}" upper="${ulimit}"/>
      <dynamics friction="0.13"/>
      <parent link="${parent}"/>
      <child link="${name}_link"/>
    </joint>

    <link name="${name}_link">
      <xacro:box_inertia length="0.025" width="0.038" height="0.009" mass="0.008"/>

      <visual>
        <origin xyz=" 0 0 0 " rpy="0 0 0"/>
        <geometry>
          <mesh filename="package://turtlebot_arm_description/meshes/F3.stl" scale="${M_SCALE} ${M_SCALE} ${M_SCALE}"/>
        </geometry>
        <material name="${color}"/>
      </visual>

      <collision>
        <origin xyz="0.0 0.0 -0.0045" rpy="0 0 0"/>
        <geometry>
          <box size="0.025 0.038 0.009"/>
        </geometry>
      </collision>
    </link>
    
    <gazebo reference="${name}_link">
      <material>Gazebo/${color}</material>
      <selfCollide>true</selfCollide>
      <gravity>true</gravity>
    </gazebo>
  </xacro:macro>

  <xacro:macro name="bioloid_F2_revolute" params="parent name color llimit ulimit vlimit *origin">
    <joint name="${name}_joint" type="revolute">
      <xacro:insert_block name="origin"/>
      <axis xyz="0 1 0"/>
      <limit effort="30" velocity="${vlimit}" lower="${llimit}" upper="${ulimit}"/>
      <dynamics friction="0.13"/>
      <parent link="${parent}"/>
      <child link="${name}_link"/>
    </joint>

    <link name="${name}_link">
      <xacro:box_inertia length="0.025" width="0.0485" height="0.0375" mass="0.010"/>

      <visual>
        <origin xyz=" 0 0 0 " rpy="0 0 0"/>
        <geometry>
          <mesh filename="package://turtlebot_arm_description/meshes/F2.stl" scale="${M_SCALE} ${M_SCALE} ${M_SCALE}"/>
        </geometry>
        <material name="${color}"/>
      </visual>

      <collision>
        <origin xyz="0.0 0.0 0.00775" rpy="0 0 0"/>
        <geometry>
          <box size="0.025 0.0485 0.0375"/>
        </geometry>
      </collision>
    </link>
    
    <gazebo reference="${name}_link">
      <material>Gazebo/${color}</material>
      <selfCollide>true</selfCollide>
      <gravity>true</gravity>
    </gazebo>
  </xacro:macro>

  <xacro:macro name="bioloid_F4_revolute" params="parent name color llimit ulimit vlimit *origin">
    <joint name="${name}_joint" type="revolute">
      <xacro:insert_block name="origin"/>
      <axis xyz="0 1 0"/>
      <limit effort="30" velocity="${vlimit}" lower="${llimit}" upper="${ulimit}"/>
      <dynamics friction="0.13"/>
      <parent link="${parent}"/>
      <child link="${name}_link"/>
    </joint>

    <link name="${name}_link">
      <xacro:box_inertia length="0.028" width="0.0485" height="0.065" mass="0.016"/>

      <visual>
        <origin xyz=" 0 0 0 " rpy="0 0 0"/>
        <geometry>
          <mesh filename="package://turtlebot_arm_description/meshes/F4.stl" scale="${M_SCALE} ${M_SCALE} ${M_SCALE}"/>
        </geometry>
        <material name="${color}"/>
      </visual>

      <collision>
        <origin xyz="0.0 0.0 0.0215" rpy="0 0 0"/>
        <geometry>
          <box size="0.028 0.0485 0.065"/>
        </geometry>
      </collision>
    </link>
    
    <gazebo reference="${name}_link">
      <material>Gazebo/${color}</material>
      <selfCollide>true</selfCollide>
      <gravity>true</gravity>
    </gazebo>
  </xacro:macro>
  
  <xacro:macro name="gripper_finger_base" params="parent name color *origin">
    <joint name="${name}_joint" type="fixed">
      <xacro:insert_block name="origin"/>
      <parent link="${parent}"/>
      <child link="${name}_link"/>
    </joint>
    
    <link name="${name}_link">
      <xacro:box_inertia length="0.002" width="0.040" height="0.075" mass="0.00001"/>
      <visual>
        <origin xyz="0.016 0 -.015 " rpy="${M_PI} ${-M_PI/2} ${M_PI/2}"/>
        <geometry>
          <mesh filename="package://turtlebot_arm_description/meshes/pincher_finger_base.stl" scale=".01 .01 .01"/>
        </geometry>
        <material name="${color}"/>
      </visual>
      
      <collision>
        <origin xyz="0.016 0.0 -0.015" rpy="0 0 0"/>
        <geometry>
          <box size="0.002 0.040 0.075"/>
        </geometry>
      </collision>
    </link >
    
    <gazebo reference="${name}_link">
      <material>Gazebo/${color}</material>
      <selfCollide>true</selfCollide>
      <gravity>true</gravity>
    </gazebo>
  </xacro:macro>
  
    <xacro:macro name="pincher_gripper" params="name color *origin">
      <link name="${name}_link">
      <xacro:box_inertia length="0.036" width="0.028" height="0.004" mass="0.00001"/>
      <visual>
        <xacro:insert_block name="origin"/>
        <geometry>
          <mesh filename="package://turtlebot_arm_description/meshes/pincher_finger.stl" scale=".01 .01 .01"/>
        </geometry>
        <material name="${color}"/>
      </visual>
      <collision>
        <xacro:insert_block name="origin"/>
        <geometry>
          <box size="0.023 0.028 0.038"/>
        </geometry>
      </collision>
    </link>
  
    <gazebo reference="${name}_link">
      <material>Gazebo/${color}</material>
      <selfCollide>true</selfCollide>
      <gravity>true</gravity>
    </gazebo>
  </xacro:macro>
</robot>
